
// | This module defines the `MonadError` type class and its instances.
"use strict";
var Control_Applicative = require("../Control.Applicative/index.js");
var Control_Bind = require("../Control.Bind/index.js");
var Control_Semigroupoid = require("../Control.Semigroupoid/index.js");
var Data_Either = require("../Data.Either/index.js");
var Data_Function = require("../Data.Function/index.js");
var Data_Functor = require("../Data.Functor/index.js");
var Data_Maybe = require("../Data.Maybe/index.js");
var Data_Unit = require("../Data.Unit/index.js");
var Prelude = require("../Prelude/index.js");

// | The `MonadThrow` type class represents those monads which support errors via
// | `throwError`, where `throwError e` halts, yielding the error `e`.
// |
// | An implementation is provided for `ExceptT`, and for other monad transformers
// | defined in this library.
// |
// | Laws:
// |
// | - Left zero: `throwError e >>= f = throwError e`
// |
var MonadThrow = function (Monad0, throwError) {
    this.Monad0 = Monad0;
    this.throwError = throwError;
};

// | The `MonadError` type class represents those monads which support catching
// | errors.
// |
// | - `catchError x f` calls the error handler `f` if an error is thrown during the
// |   evaluation of `x`.
// |
// | An implementation is provided for `ExceptT`, and for other monad transformers
// | defined in this library.
// |
// | Laws:
// |
// | - Catch: `catchError (throwError e) f = f e`
// | - Pure: `catchError (pure a) f = pure a`
// |
var MonadError = function (MonadThrow0, catchError) {
    this.MonadThrow0 = MonadThrow0;
    this.catchError = catchError;
};
var throwError = function (dict) {
    return dict.throwError;
};
var monadThrowMaybe = new MonadThrow(function () {
    return Data_Maybe.monadMaybe;
}, Data_Function["const"](Data_Maybe.Nothing.value));
var monadThrowEither = new MonadThrow(function () {
    return Data_Either.monadEither;
}, Data_Either.Left.create);
var monadErrorMaybe = new MonadError(function () {
    return monadThrowMaybe;
}, function (v) {
    return function (v1) {
        if (v instanceof Data_Maybe.Nothing) {
            return v1(Data_Unit.unit);
        };
        if (v instanceof Data_Maybe.Just) {
            return new Data_Maybe.Just(v.value0);
        };
        throw new Error("Failed pattern match at Control.Monad.Error.Class line 76, column 1 - line 76, column 50: " + [ v.constructor.name, v1.constructor.name ]);
    };
});
var monadErrorEither = new MonadError(function () {
    return monadThrowEither;
}, function (v) {
    return function (v1) {
        if (v instanceof Data_Either.Left) {
            return v1(v.value0);
        };
        if (v instanceof Data_Either.Right) {
            return new Data_Either.Right(v.value0);
        };
        throw new Error("Failed pattern match at Control.Monad.Error.Class line 69, column 1 - line 69, column 53: " + [ v.constructor.name, v1.constructor.name ]);
    };
});
var catchError = function (dict) {
    return dict.catchError;
};

// | This function allows you to provide a predicate for selecting the
// | exceptions that you're interested in, and handle only those exceptons.
// | If the inner computation throws an exception, and the predicate returns
// | Nothing, then the whole computation will still fail with that exception.
var catchJust = function (dictMonadError) {
    return function (p) {
        return function (act) {
            return function (handler) {
                var handle = function (e) {
                    var v = p(e);
                    if (v instanceof Data_Maybe.Nothing) {
                        return throwError(dictMonadError.MonadThrow0())(e);
                    };
                    if (v instanceof Data_Maybe.Just) {
                        return handler(v.value0);
                    };
                    throw new Error("Failed pattern match at Control.Monad.Error.Class line 54, column 5 - line 56, column 26: " + [ v.constructor.name ]);
                };
                return catchError(dictMonadError)(act)(handle);
            };
        };
    };
};

// | Return `Right` if the given action succeeds, `Left` if it throws.
var $$try = function (dictMonadError) {
    return function (a) {
        return catchError(dictMonadError)(Data_Functor.map(((((dictMonadError.MonadThrow0()).Monad0()).Bind1()).Apply0()).Functor0())(Data_Either.Right.create)(a))(function ($21) {
            return Control_Applicative.pure(((dictMonadError.MonadThrow0()).Monad0()).Applicative0())(Data_Either.Left.create($21));
        });
    };
};

// | Make sure that a resource is cleaned up in the event of an exception. The
// | release action is called regardless of whether the body action throws or
// | returns.
var withResource = function (dictMonadError) {
    return function (acquire) {
        return function (release) {
            return function (kleisli) {
                return Control_Bind.bind(((dictMonadError.MonadThrow0()).Monad0()).Bind1())(acquire)(function (v) {
                    return Control_Bind.bind(((dictMonadError.MonadThrow0()).Monad0()).Bind1())($$try(dictMonadError)(kleisli(v)))(function (v1) {
                        return Control_Bind.discard(Control_Bind.discardUnit)(((dictMonadError.MonadThrow0()).Monad0()).Bind1())(release(v))(function () {
                            return Data_Either.either(throwError(dictMonadError.MonadThrow0()))(Control_Applicative.pure(((dictMonadError.MonadThrow0()).Monad0()).Applicative0()))(v1);
                        });
                    });
                });
            };
        };
    };
};
module.exports = {
    catchError: catchError,
    throwError: throwError,
    MonadThrow: MonadThrow,
    MonadError: MonadError,
    catchJust: catchJust,
    "try": $$try,
    withResource: withResource,
    monadThrowEither: monadThrowEither,
    monadErrorEither: monadErrorEither,
    monadThrowMaybe: monadThrowMaybe,
    monadErrorMaybe: monadErrorMaybe
};
